Workbook

Sheet comparison
A3: Row Labels | B3: Max of opt_bound | C3: Min of cost | F3: Row Labels | G3: Max of opt_bound | H3: Min of cost | I3: rmp_opt | J3: rmp_ub | K3: improved bound | L3: improved UB | M3: best ub | N3: best_bnd | O3: isopt | P3: best_gap
A4: a10100_0 | B4: 1370 | C4: 1370 | F4: new1201600_30_ada | G4: 3193 | H4: 5130 | I4: 3978 | J4: =VLOOKUP(F4,rmp_opt!$A$2:$C$1736,3,FALSE) -> 6644 | K4: =IF(I4>G4,1,0) -> 1 | L4: =IF(J4<H4,1,0) -> 0 | M4: =MIN(J4,H4) -> 5130 | N4: =MAX(I4,G4) -> 3978 | O4: =IF(N4=M4,1,0) -> 0 | P4: =(M4-N4)/M4 -> 0.2245614
A5: a10100_1 | B5: 1326 | C5: 1326 | F5: new1605000_31_ada | G5: 6686 | H5: 12193.333 | I5: 8524 | J5: =VLOOKUP(F5,rmp_opt!$A$2:$C$1736,3,FALSE) -> 10693 | K5: =IF(I5>G5,1,0) -> 1 | L5: =IF(J5<H5,1,0) -> 1 | M5: =MIN(J5,H5) -> 10693 | N5: =MAX(I5,G5) -> 8524 | O5: =IF(N5=M5,1,0) -> 0 | P5: =(M5-N5)/M5 -> 0.20284298
A6: a10100_2 | B6: 1262 | C6: 1262 | F6: f2004000_2 | G6: 380435 | H6: 583129.33 | I6: 384314 | J6: =VLOOKUP(F6,rmp_opt!$A$2:$C$1736,3,FALSE) -> 473231 | K6: =IF(I6>G6,1,0) -> 1 | L6: =IF(J6<H6,1,0) -> 1 | M6: =MIN(J6,H6) -> 473231 | N6: =MAX(I6,G6) -> 384314 | O6: =IF(N6=M6,1,0) -> 0 | P6: =(M6-N6)/M6 -> 0.18789344
A7: a10100_3 | B7: 1340 | C7: 1340 | F7: f1604000_8 | G7: 412092 | H7: 581939 | I7: 414072 | J7: =VLOOKUP(F7,rmp_opt!$A$2:$C$1736,3,FALSE) -> 492548 | K7: =IF(I7>G7,1,0) -> 1 | L7: =IF(J7<H7,1,0) -> 1 | M7: =MIN(J7,H7) -> 492548 | N7: =MAX(I7,G7) -> 414072 | O7: =IF(N7=M7,1,0) -> 0 | P7: =(M7-N7)/M7 -> 0.1593266
A8: a10100_4 | B8: 1315 | C8: 1315 | F8: f2005000_6 | G8: 426409 | H8: 757613.67 | I8: 429211 | J8: =VLOOKUP(F8,rmp_opt!$A$2:$C$1736,3,FALSE) -> 498773 | K8: =IF(I8>G8,1,0) -> 1 | L8: =IF(J8<H8,1,0) -> 1 | M8: =MIN(J8,H8) -> 498773 | N8: =MAX(I8,G8) -> 429211 | O8: =IF(N8=M8,1,0) -> 0 | P8: =(M8-N8)/M8 -> 0.13946625
A9: a10100_5 | B9: 1346 | C9: 1346 | F9: f80900_5 | G9: 193438 | H9: 242483.67 | I9: 195423 | J9: =VLOOKUP(F9,rmp_opt!$A$2:$C$1736,3,FALSE) -> 223763 | K9: =IF(I9>G9,1,0) -> 1 | L9: =IF(J9<H9,1,0) -> 1 | M9: =MIN(J9,H9) -> 223763 | N9: =MAX(I9,G9) -> 195423 | O9: =IF(N9=M9,1,0) -> 0 | P9: =(M9-N9)/M9 -> 0.12665186
A10: a10100_6 | B10: 1331 | C10: 1331 | F10: f2004000 | G10: 326110 | H10: 496342 | I10: 328306 | J10: =VLOOKUP(F10,rmp_opt!$A$2:$C$1736,3,FALSE) -> 375044 | K10: =IF(I10>G10,1,0) -> 1 | L10: =IF(J10<H10,1,0) -> 1 | M10: =MIN(J10,H10) -> 375044 | N10: =MAX(I10,G10) -> 328306 | O10: =IF(N10=M10,1,0) -> 0 | P10: =(M10-N10)/M10 -> 0.12462004
A11: a10100_7 | B11: 1281 | C11: 1281 | F11: f80900_7 | G11: 254173 | H11: 321474 | I11: 256978 | J11: =VLOOKUP(F11,rmp_opt!$A$2:$C$1736,3,FALSE) -> 293446 | K11: =IF(I11>G11,1,0) -> 1 | L11: =IF(J11<H11,1,0) -> 1 | M11: =MIN(J11,H11) -> 293446 | N11: =MAX(I11,G11) -> 256978 | O11: =IF(N11=M11,1,0) -> 0 | P11: =(M11-N11)/M11 -> 0.12427499
A12: a10100_8 | B12: 1328 | C12: 1328 | F12: f2004000_4 | G12: 326942 | H12: 502120 | I12: 329125 | J12: =VLOOKUP(F12,rmp_opt!$A$2:$C$1736,3,FALSE) -> 374683 | K12: =IF(I12>G12,1,0) -> 1 | L12: =IF(J12<H12,1,0) -> 1 | M12: =MIN(J12,H12) -> 374683 | N12: =MAX(I12,G12) -> 329125 | O12: =IF(N12=M12,1,0) -> 0 | P12: =(M12-N12)/M12 -> 0.12159078
A13: a10100_9 | B13: 1347 | C13: 1347 | F13: f801600_1 | G13: 306272 | H13: 368440.33 | I13: 307995 | J13: =VLOOKUP(F13,rmp_opt!$A$2:$C$1736,3,FALSE) -> 348370 | K13: =IF(I13>G13,1,0) -> 1 | L13: =IF(J13<H13,1,0) -> 1 | M13: =MIN(J13,H13) -> 348370 | N13: =MAX(I13,G13) -> 307995 | O13: =IF(N13=M13,1,0) -> 0 | P13: =(M13-N13)/M13 -> 0.11589689
A14: a10200_0 | B14: 2734 | C14: 2734 | F14: f1603200_3 | G14: 356180 | H14: 609372.67 | I14: 358531 | J14: =VLOOKUP(F14,rmp_opt!$A$2:$C$1736,3,FALSE) -> 402713 | K14: =IF(I14>G14,1,0) -> 1 | L14: =IF(J14<H14,1,0) -> 1 | M14: =MIN(J14,H14) -> 402713 | N14: =MAX(I14,G14) -> 358531 | O14: =IF(N14=M14,1,0) -> 0 | P14: =(M14-N14)/M14 -> 0.10971089
A15: a10200_1 | B15: 2690 | C15: 2690 | F15: f1201600_7 | G15: 239203 | H15: 319237.33 | I15: 241319 | J15: =VLOOKUP(F15,rmp_opt!$A$2:$C$1736,3,FALSE) -> 268035 | K15: =IF(I15>G15,1,0) -> 1 | L15: =IF(J15<H15,1,0) -> 1 | M15: =MIN(J15,H15) -> 268035 | N15: =MAX(I15,G15) -> 241319 | O15: =IF(N15=M15,1,0) -> 0 | P15: =(M15-N15)/M15 -> 0.09967355
... A36: a20200_2 | B36: 2340 | C36: 2340 | F36: f1604000_0 | G36: 385100 | H36: 536779.33 | I36: 386967 | J36: =VLOOKUP(F36,rmp_opt!$A$2:$C$1736,3,FALSE) -> 414138 | K36: =IF(I36>G36,1,0) -> 1 | L36: =IF(J36<H36,1,0) -> 1 | M36: =MIN(J36,H36) -> 414138 | N36: =MAX(I36,G36) -> 386967 | O36: =IF(N36=M36,1,0) -> 0 | P36: =(M36-N36)/M36 -> 0.065608565
A37: a20200_3 | B37: 2295 | C37: 2295 | F37: new1605000_34_aac | H37: 315441 | I37: 214251 | J37: =VLOOKUP(F37,rmp_opt!$A$2:$C$1736,3,FALSE) -> 229122 | K37: =IF(I37>G37,1,0) -> 1 | L37: =IF(J37<H37,1,0) -> 1 | M37: =MIN(J37,H37) -> 229122 | N37: =MAX(I37,G37) -> 214251 | O37: =IF(N37=M37,1,0) -> 0 | P37: =(M37-N37)/M37 -> 0.064904287
A38: a20200_4 | B38: 2257 | C38: 2257 | F38: f1603200_8 | G38: 315113 | H38: 339178 | I38: 317219 | J38: =VLOOKUP(F38,rmp_opt!$A$2:$C$1736,3,FALSE) -> 343350 | K38: =IF(I38>G38,1,0) -> 1 | L38: =IF(J38<H38,1,0) -> 0 | M38: =MIN(J38,H38) -> 339178 | N38: =MAX(I38,G38) -> 317219 | O38: =IF(N38=M38,1,0) -> 0 | P38: =(M38-N38)/M38 -> 0.064741817
A39: a20200_5 | B39: 2304 | C39: 2304 | F39: f1201600_5 | G39: 197725 | H39: 213033 | I39: 199464 | J39: =VLOOKUP(F39,rmp_opt!$A$2:$C$1736,3,FALSE) -> 215081 | K39: =IF(I39>G39,1,0) -> 1 | L39: =IF(J39<H39,1,0) -> 0 | M39: =MIN(J39,H39) -> 213033 | N39: =MAX(I39,G39) -> 199464 | O39: =IF(N39=M39,1,0) -> 0 | P39: =(M39-N39)/M39 -> 0.063694357
A40: a20200_6 | B40: 2231 | C40: 2231 | F40: f1203200_2 | G40: 402987 | H40: 448564 | I40: 404674 | J40: =VLOOKUP(F40,rmp_opt!$A$2:$C$1736,3,FALSE) -> 432184 | K40: =IF(I40>G40,1,0) -> 1 | L40: =IF(J40<H40,1,0) -> 1 | M40: =MIN(J40,H40) -> 432184 | N40: =MAX(I40,G40) -> 404674 | O40: =IF(N40=M40,1,0) -> 0 | P40: =(M40-N40)/M40 -> 0.063653444
A41: a20200_7 | B41: 2290 | C41: 2290 | F41: f801600_5 | G41: 342179 | H41: 367273 | I41: 344101 | J41: =VLOOKUP(F41,rmp_opt!$A$2:$C$1736,3,FALSE) -> 372047 | K41: =IF(I41>G41,1,0) -> 1 | L41: =IF(J41<H41,1,0) -> 0 | M41: =MIN(J41,H41) -> 367273 | N41: =MAX(I41,G41) -> 344101 | O41: =IF(N41=M41,1,0) -> 0 | P41: =(M41-N41)/M41 -> 0.063092032
A42: a20200_8 | B42: 2245 | C42: 2245 | F42: new60900_33_aac | G42: 205041 | H42: 220141 | I42: 206336 | J42: =VLOOKUP(F42,rmp_opt!$A$2:$C$1736,3,FALSE) -> 236004 | K42: =IF(I42>G42,1,0) -> 1 | L42: =IF(J42<H42,1,0) -> 0 | M42: =MIN(J42,H42) -> 220141 | N42: =MAX(I42,G42) -> 206336 | O42: =IF(N42=M42,1,0) -> 0 | P42: =(M42-N42)/M42 -> 0.062709809
A43: a20200_9 | B43: 2308 | C43: 2308 | F43: f1604000_1 | G43: 451239 | H43: 501924 | I43: 454124 | J43: =VLOOKUP(F43,rmp_opt!$A$2:$C$1736,3,FALSE) -> 484440 | K43: =IF(I43>G43,1,0) -> 1 | L43: =IF(J43<H43,1,0) -> 1 | M43: =MIN(J43,H43) -> 484440 | N43: =MAX(I43,G43) -> 454124 | O43: =IF(N43=M43,1,0) -> 0 | P43: =(M43-N43)/M43 -> 0.062579473
A44: a5100_0 | B44: 1591 | C44: 1591 | F44: f1604000_4 | G44: 375900 | H44: 426271 | I44: 377773 | J44: =VLOOKUP(F44,rmp_opt!$A$2:$C$1736,3,FALSE) -> 402367 | K44: =IF(I44>G44,1,0) -> 1 | L44: =IF(J44<H44,1,0) -> 1 | M44: =MIN(J44,H44) -> 402367 | N44: =MAX(I44,G44) -> 377773 | O44: =IF(N44=M44,1,0) -> 0 | P44: =(M44-N44)/M44 -> 0.061123303
A45: a5100_1 | B45: 1612 | C45: 1612 | F45: f1204000_7 | G45: 471932 | H45: 504154 | I45: 473469 | J45: =VLOOKUP(F45,rmp_opt!$A$2:$C$1736,3,FALSE) -> 506080 | K45: =IF(I45>G45,1,0) -> 1 | L45: =IF(J45<H45,1,0) -> 0 | M45: =MIN(J45,H45) -> 504154 | N45: =MAX(I45,G45) -> 473469 | O45: =IF(N45=M45,1,0) -> 0 | P45: =(M45-N45)/M45 -> 0.060864339
A46: a5100_2 | B46: 1629 | C46: 1629 | F46: new1205000_18_ada | G46: 6538 | H46: 9943.6667 | I46: 6804 | J46: =VLOOKUP(F46,rmp_opt!$A$2:$C$1736,3,FALSE) -> 7242 | K46: =IF(I46>G46,1,0) -> 1 | L46: =IF(J46<H46,1,0) -> 1 | M46: =MIN(J46,H46) -> 7242 | N46: =MAX(I46,G46) -> 6804 | O46: =IF(N46=M46,1,0) -> 0 | P46: =(M46-N46)/M46 -> 0.06048053
A47: a5100_3 | B47: 1592 | C47: 1592 | F47: f1604000_7 | G47: 405535 | H47: 452869 | I47: 407618 | J47: =VLOOKUP(F47,rmp_opt!$A$2:$C$1736,3,FALSE) -> 433336 | K47: =IF(I47>G47,1,0) -> 1 | L47: =IF(J47<H47,1,0) -> 1 | M47: =MIN(J47,H47) -> 433336 | N47: =MAX(I47,G47) -> 407618 | O47: =IF(N47=M47,1,0) -> 0 | P47: =(M47-N47)/M47 -> 0.059348866
A48: a5100_4 | B48: 1601 | C48: 1601 | F48: f1603200_6 | G48: 292397 | H48: 315896 | I48: 294378 | J48: =VLOOKUP(F48,rmp_opt!$A$2:$C$1736,3,FALSE) -> 312918 | K48: =IF(I48>G48,1,0) -> 1 | L48: =IF(J48<H48,1,0) -> 1 | M48: =MIN(J48,H48) -> 312918 | N48: =MAX(I48,G48) -> 294378 | O48: =IF(N48=M48,1,0) -> 0 | P48: =(M48-N48)/M48 -> 0.059248749
A49: a5100_5 | B49: 1636 | C49: 1636 | F49: f1201600_0 | G49: 201697 | H49: 216181 | I49: 203375 | J49: =VLOOKUP(F49,rmp_opt!$A$2:$C$1736,3,FALSE) -> 264405 | K49: =IF(I49>G49,1,0) -> 1 | L49: =IF(J49<H49,1,0) -> 0 | M49: =MIN(J49,H49) -> 216181 | N49: =MAX(I49,G49) -> 203375 | O49: =IF(N49=M49,1,0) -> 0 | P49: =(M49-N49)/M49 -> 0.059237398
... A79: b10200_5 | B79: 2671 | C79: 2671 | F79: f2005000_4 | G79: 395191 | H79: 591020 | I79: 397754 | J79: =VLOOKUP(F79,rmp_opt!$A$2:$C$1736,3,FALSE) -> 417742 | K79: =IF(I79>G79,1,0) -> 1 | L79: =IF(J79<H79,1,0) -> 1 | M79: =MIN(J79,H79) -> 417742 | N79: =MAX(I79,G79) -> 397754 | O79: =IF(N79=M79,1,0) -> 0 | P79: =(M79-N79)/M79 -> 0.047847715
A80: b10200_6 | B80: 2895 | C80: 2895 | F80: f1205000_5 | H80: 1160478.7 | I80: 766005 | J80: =VLOOKUP(F80,rmp_opt!$A$2:$C$1736,3,FALSE) -> 804379 | K80: =IF(I80>G80,1,0) -> 1 | L80: =IF(J80<H80,1,0) -> 1 | M80: =MIN(J80,H80) -> 804379 | N80: =MAX(I80,G80) -> 766005 | O80: =IF(N80=M80,1,0) -> 0 | P80: =(M80-N80)/M80 -> 0.047706367
A81: b10200_7 | B81: 2798 | C81: 2798 | F81: new80900_3_aec | G81: 2872 | H81: 3028 | I81: 2886 | J81: =VLOOKUP(F81,rmp_opt!$A$2:$C$1736,3,FALSE) -> 3296 | K81: =IF(I81>G81,1,0) -> 1 | L81: =IF(J81<H81,1,0) -> 0 | M81: =MIN(J81,H81) -> 3028 | N81: =MAX(I81,G81) -> 2886 | O81: =IF(N81=M81,1,0) -> 0 | P81: =(M81-N81)/M81 -> 0.046895641
A82: b10200_8 | B82: 2807 | C82: 2807 | F82: new2005000_15_aec | G82: 14286 | H82: 15003 | I82: 14303 | J82: =VLOOKUP(F82,rmp_opt!$A$2:$C$1736,3,FALSE) -> 15078 | K82: =IF(I82>G82,1,0) -> 1 | L82: =IF(J82<H82,1,0) -> 0 | M82: =MIN(J82,H82) -> 15003 | N82: =MAX(I82,G82) -> 14303 | O82: =IF(N82=M82,1,0) -> 0 | P82: =(M82-N82)/M82 -> 0.046657335
A83: b10200_9 | B83: 2929 | C83: 2929 | F83: f2005000_2 | G83: 446431 | H83: 730065.67 | I83: 449431 | J83: =VLOOKUP(F83,rmp_opt!$A$2:$C$1736,3,FALSE) -> 471360 | K83: =IF(I83>G83,1,0) -> 1 | L83: =IF(J83<H83,1,0) -> 1 | M83: =MIN(J83,H83) -> 471360 | N83: =MAX(I83,G83) -> 449431 | O83: =IF(N83=M83,1,0) -> 0 | P83: =(M83-N83)/M83 -> 0.046522828
A84: b20100_0 | B84: 1167 | C84: 1167 | F84: f1201600_4 | G84: 218742 | H84: 231562 | I84: 220824 | J84: =VLOOKUP(F84,rmp_opt!$A$2:$C$1736,3,FALSE) -> 244959 | K84: =IF(I84>G84,1,0) -> 1 | L84: =IF(J84<H84,1,0) -> 0 | M84: =MIN(J84,H84) -> 231562 | N84: =MAX(I84,G84) -> 220824 | O84: =IF(N84=M84,1,0) -> 0 | P84: =(M84-N84)/M84 -> 0.04637203
A85: b20100_1 | B85: 1183 | C85: 1183 | F85: f2004000_8 | G85: 303864 | H85: 344906 | I85: 305961 | J85: =VLOOKUP(F85,rmp_opt!$A$2:$C$1736,3,FALSE) -> 320830 | K85: =IF(I85>G85,1,0) -> 1 | L85: =IF(J85<H85,1,0) -> 1 | M85: =MIN(J85,H85) -> 320830 | N85: =MAX(I85,G85) -> 305961 | O85: =IF(N85=M85,1,0) -> 0 | P85: =(M85-N85)/M85 -> 0.046345417
A86: b20100_2 | B86: 1175 | C86: 1175 | F86: f1205000 | G86: 644334 | H86: 685145 | I86: 646010 | J86: =VLOOKUP(F86,rmp_opt!$A$2:$C$1736,3,FALSE) -> 677294 | K86: =IF(I86>G86,1,0) -> 1 | L86: =IF(J86<H86,1,0) -> 1 | M86: =MIN(J86,H86) -> 677294 | N86: =MAX(I86,G86) -> 646010 | O86: =IF(N86=M86,1,0) -> 0 | P86: =(M86-N86)/M86 -> 0.04618969
A87: b20100_3 | B87: 1201 | C87: 1201 | F87: f1205000_8 | G87: 751875 | H87: 829345 | I87: 753942 | J87: =VLOOKUP(F87,rmp_opt!$A$2:$C$1736,3,FALSE) -> 790209 | K87: =IF(I87>G87,1,0) -> 1 | L87: =IF(J87<H87,1,0) -> 1 | M87: =MIN(J87,H87) -> 790209 | N87: =MAX(I87,G87) -> 753942 | O87: =IF(N87=M87,1,0) -> 0 | P87: =(M87-N87)/M87 -> 0.045895453
A88: b20100_4 | B88: 1149 | C88: 1149 | F88: f1605000_9 | G88: 507698 | H88: 835270.67 | I88: 509520 | J88: =VLOOKUP(F88,rmp_opt!$A$2:$C$1736,3,FALSE) -> 533769 | K88: =IF(I88>G88,1,0) -> 1 | L88: =IF(J88<H88,1,0) -> 1 | M88: =MIN(J88,H88) -> 533769 | N88: =MAX(I88,G88) -> 509520 | O88: =IF(N88=M88,1,0) -> 0 | P88: =(M88-N88)/M88 -> 0.045429765
A89: b20100_5 | B89: 1178 | C89: 1178 | F89: f1205000_9 | G89: 603737 | H89: 761353.67 | I89: 605081 | J89: =VLOOKUP(F89,rmp_opt!$A$2:$C$1736,3,FALSE) -> 632876 | K89: =IF(I89>G89,1,0) -> 1 | L89: =IF(J89<H89,1,0) -> 1 | M89: =MIN(J89,H89) -> 632876 | N89: =MAX(I89,G89) -> 605081 | O89: =IF(N89=M89,1,0) -> 0 | P89: =(M89-N89)/M89 -> 0.043918556
A90: b20100_6 | B90: 1203 | C90: 1203 | F90: new1605000_22_aec | G90: 6400 | H90: 6705 | I90: 6411 | J90: =VLOOKUP(F90,rmp_opt!$A$2:$C$1736,3,FALSE) -> 6795 | K90: =IF(I90>G90,1,0) -> 1 | L90: =IF(J90<H90,1,0) -> 0 | M90: =MIN(J90,H90) -> 6705 | N90: =MAX(I90,G90) -> 6411 | O90: =IF(N90=M90,1,0) -> 0 | P90: =(M90-N90)/M90 -> 0.043847875
A91: b20100_7 | B91: 1184 | C91: 1184 | F91: new1603200_34_ada | G91: 57115 | H91: 59715 | I91: 57164 | J91: =VLOOKUP(F91,rmp_opt!$A$2:$C$1736,3,FALSE) -> 59889 | K91: =IF(I91>G91,1,0) -> 1 | L91: =IF(J91<H91,1,0) -> 0 | M91: =MIN(J91,H91) -> 59715 | N91: =MAX(I91,G91) -> 57164 | O91: =IF(N91=M91,1,0) -> 0 | P91: =(M91-N91)/M91 -> 0.042719585
...

Sheet isa_paper_results
A1: instance | B1: cost | C1: time_used | D1: optimal | E1: opt_bound | F1: solver | G1: rel_to_best | H1: area_score
A2: a10100_0 | B2: 1370 | C2: 4960 | D2: TRUE | E2: 1370 | F2: minizinc_chuffed | G2: 0 | H2: 5176.3607
A3: a10100_0 | B3: 1370 | C3: 270 | D3: TRUE | E3: 1370 | F3: minizinc_cplex | G3: 0 | H3: 366.91635
A4: a10100_0 | B4: 1370 | C4: 1420 | D4: TRUE | E4: 1370 | F4: minizinc_cpo | G4: 0 | H4: 1680.0134
A5: a10100_0 | B5: 1370 | C5: 220 | D5: TRUE | E5: 1370 | F5: minizinc_gurobi | G5: 0 | H5: 301.00592
A6: a10100_0 | B6: 1370 | C6: 1790 | D6: TRUE | E6: 1370 | F6: minizinc_or-tools | G6: 0 | H6: 2299.9139
A7: a10100_0 | B7: 1370 | C7: FALSE | D7: 900000 | F7: min_conflicts | G7: 0 | H7: 612492.28
A8: a10100_0 | B8: 1370 | C8: FALSE | D8: 900000 | F8: simulated_annealing-untuned | G8: 0 | H8: 821955.91
A9: a10100_0 | B9: 1372 | C9: FALSE | D9: 900000 | F9: tabu_search | G9: 0.0014577259 | H9: 613061.51
A10: a10100_1 | B10: 1326 | C10: 4510 | D10: TRUE | E10: 1326 | F10: minizinc_chuffed | G10: 0 | H10: 4713.836
A11: a10100_1 | B11: 1326 | C11: 300 | D11: TRUE | E11: 1326 | F11: minizinc_cplex | G11: 0 | H11: 399.88127
A12: a10100_1 | B12: 1326 | C12: 1220 | D12: TRUE | E12: 1326 | F12: minizinc_cpo | G12: 0 | H12: 1520.6544
A13: a10100_1 | B13: 1326 | C13: 200 | D13: TRUE | E13: 1326 | F13: minizinc_gurobi | G13: 0 | H13: 254.93931
A14: a10100_1 | B14: 1326 | C14: 1860 | D14: TRUE | E14: 1326 | F14: minizinc_or-tools | G14: 0 | H14: 2353.4156
A15: a10100_1 | B15: 1326 | C15: FALSE | D15: 900000 | F15: min_conflicts | G15: 0 | H15: 584242.03
A16: a10100_1 | B16: 1326 | C16: FALSE | D16: 900000 | F16: simulated_annealing-untuned | G16: 0 | H16: 794528.18
A17: a10100_1 | B17: 1326 | C17: FALSE | D17: 900000 | F17: tabu_search | G17: 0 | H17: 584248.46
A18: a10100_2 | B18: 1262 | C18: 5080 | D18: TRUE | E18: 1262 | F18: minizinc_chuffed | G18: 0 | H18: 5674.2756
A19: a10100_2 | B19: 1262 | C19: 510 | D19: TRUE | E19: 1262 | F19: minizinc_cplex | G19: 0 | H19: 699.89411
A20: a10100_2 | B20: 1262 | C20: 300 | D20: TRUE | E20: 1262 | F20: minizinc_cpo | G20: 0 | H20: 416.11418
A21: a10100_2 | B21: 1262 | C21: 200 | D21: TRUE | E21: 1262 | F21: minizinc_gurobi | G21: 0 | H21: 262.43708
A22: a10100_2 | B22: 1262 | C22: 650 | D22: TRUE | E22: 1262 | F22: minizinc_or-tools | G22: 0 | H22: 781.9644
A23: a10100_2 | B23: 1262 | C23: FALSE | D23: 900000 | F23: min_conflicts | G23: 0 | H23: 569391.06
A24: a10100_2 | B24: 1262 | C24: FALSE | D24: 900000 | F24: simulated_annealing-untuned | G24: 0 | H24: 773094.81
A25: a10100_2 | B25: 1269.3333 | C25: FALSE | D25: 900000 | F25: tabu_search | G25: 0.0057773109 | H25: 570484.8
A26: a10100_3 | B26: 1340 | C26: 4590 | D26: TRUE | E26: 1340 | F26: minizinc_chuffed | G26: 0 | H26: 4936.9626
A27: a10100_3 | B27: 1340 | C27: 360 | D27: TRUE | E27: 1340 | F27: minizinc_cplex | G27: 0 | H27: 482.17786
A28: a10100_3 | B28: 1340 | C28: 740 | D28: TRUE | E28: 1340 | F28: minizinc_cpo | G28: 0 | H28: 679.65033
A29: a10100_3 | B29: 1340 | C29: 230 | D29: TRUE | E29: 1340 | F29: minizinc_gurobi | G29: 0 | H29: 299.81278
A30: a10100_3 | B30: 1340 | C30: 1890 | D30: TRUE | E30: 1340 | F30: minizinc_or-tools | G30: 0 | H30: 2348.1608
A31: a10100_3 | B31: 1340 | C31: FALSE | D31: 900000 | F31: min_conflicts | G31: 0 | H31: 588911.01
A32: a10100_3 | B32: 1340 | C32: FALSE | D32: 900000 | F32: simulated_annealing-untuned | G32: 0 | H32: 807227.53
A33: a10100_3 | B33: 1342 | C33: FALSE | D33: 900000 | F33: tabu_search | G33: 0.001490313 | H33: 589731.26
A34: a10100_4 | B34: 1315 | C34: 4790 | D34: TRUE | E34: 1315 | F34: minizinc_chuffed | G34: 0 | H34: 5123.7244
A35: a10100_4 | B35: 1315 | C35: 240 | D35: TRUE | E35: 1315 | F35: minizinc_cplex | G35: 0 | H35: 329.06794
A36: a10100_4 | B36: 1315 | C36: 270 | D36: TRUE | E36: 1315 | F36: minizinc_cpo | G36: 0 | H36: 373.01394
A37: a10100_4 | B37: 1315 | C37: 180 | D37: TRUE | E37: 1315 | F37: minizinc_gurobi | G37: 0 | H37: 241.18757
A38: a10100_4 | B38: 1315 | C38: 910 | D38: TRUE | E38: 1315 | F38: minizinc_or-tools | G38: 0 | H38: 981.60859
A39: a10100_4 | B39: 1315 | C39: FALSE | D39: 900000 | F39: min_conflicts | G39: 0 | H39: 571255.19
A40: a10100_4 | B40: 1315 | C40: FALSE | D40: 900000 | F40: simulated_annealing-untuned | G40: 0 | H40: 775788.32
...

Sheet rmp_opt
A1: instance | B1: rmp_opt | C1: ub
A2: a10100_0 | B2: 1370 | C2: 1370
A3: a10100_1 | B3: 1326 | C3: 1326
A4: a10100_2 | B4: 1262 | C4: 1262
A5: a10100_3 | B5: 1340 | C5: 1340
A6: a10100_4 | B6: 1315 | C6: 1315
A7: a10100_5 | B7: 1346 | C7: 1346
A8: a10100_6 | B8: 1331 | C8: 1331
A9: a10100_7 | B9: 1281 | C9: 1281
A10: a10100_8 | B10: 1328 | C10: 1328
A11: a10100_9 | B11: 1347 | C11: 1347
A12: a10200_0 | B12: 2734 | C12: 2734
A13: a10200_1 | B13: 2690 | C13: 2690
... A717: f80900_1 | B717: 220160 | C717: 243596
A718: f80900_2 | B718: 163312 | C718: inf
A719: f80900_3 | B719: 168898 | C719: 188735
A720: f80900_4 | B720: 226791 | C720: 239388
A721: f80900_5 | B721: 195423 | C721: 223763
A722: f80900_6 | B722: 169928 | C722: inf
A723: f80900_7 | B723: 256978 | C723: 293446
A724: f80900_8 | B724: 181112 | C724: 193015
A725: f80900_9 | B725: 174495 | C725: 197453
A726: new10100_0_eec | B726: 20896 | C726: 21230
A727: new10100_1_eea | B727: 4751 | C727: 4922
A728: new10100_10_eea | B728: 3447 | C728: 3459
A729: new10100_11_adc | B729: 26919 | C729: 27765
A730: new10100_12_eaa | B730: 2630 | C730: 2630
A731: new10100_13_eec | B731: 18728 | C731: 18771
A732: new10100_14_edc | B732: 8543 | C732: 8561
A733: new10100_15_aac | B733: 14269 | C733: 14943
A734: new10100_16_aac | B734: 11263 | C734: 11322
... A904: new1204000_13_adc | B904: 491009 | C904: 493590
A905: new1204000_14_aec | B905: 119825 | C905: inf
A906: new1204000_15_eda | B906: 246995 | C906: 247840
A907: new1204000_16_eda | B907: 226013 | C907: 227066
A908: new1204000_17_eaa | B908: 60107 | C908: 60107
A909: new1204000_18_aac | B909: 51414 | C909: 51534
A910: new1204000_19_ada | B910: 609536 | C910: 614620
A911: new1204000_2_eea | B911: 83009 | C911: 84151
A912: new1204000_20_aea | B912: 4000 | C912: 4000
...
